# 🎯 后端Progress_Callback参数错误修复总结

## 📋 问题描述

用户报告的错误：
```
2025-10-09 11:53:35,838 | web | ERROR | 进度回调错误: run_stock_analysis.<locals>.progress_callback() takes from 1 to 2 positional arguments but 3 were given
```

## 🔍 问题分析

### 1. 架构确认
- **前端**: React + Ant Design + Vite (在 `frontend/` 目录)
- **后端**: Python FastAPI (在 `backend/` 目录)  
- **旧Streamlit**: 在 `web/` 目录，可能不再使用但仍有服务运行

### 2. 错误根源
错误发生在 `backend/services/analysis_service.py` 第205行：

**修复前**:
```python
def sync_progress_callback(message: str, step: int = None):  # 只支持2个参数
    # Schedule the async callback
    try:
        future = asyncio.run_coroutine_threadsafe(progress_callback(message, step), loop)
        future.result(timeout=1.0)
    except Exception as e:
        logger.error(f"Sync progress callback error: {e}")
```

**问题**: 当 `run_stock_analysis` 调用 `progress_callback("消息", 1, 10)` 传递3个参数时，`sync_progress_callback` 只能接受2个参数，导致错误。

## ✅ 修复方案

### 修复 backend/services/analysis_service.py

**修复后**:
```python
def sync_progress_callback(message: str, step: int = None, total_steps: int = None):  # 支持3个参数
    # Schedule the async callback - 支持3个参数
    try:
        future = asyncio.run_coroutine_threadsafe(progress_callback(message, step, total_steps), loop)
        future.result(timeout=1.0)
    except Exception as e:
        logger.error(f"Sync progress callback error: {e}")
```

### 调用链分析

```
backend/tradingagents_server.py (简化版run_stock_analysis)
    ↓ 调用 progress_callback("🚀 开始分析...", 1, 10)  # 3个参数
    ↓
backend/services/analysis_service.py (sync_progress_callback)
    ↓ 接收3个参数 ✅ (修复后)
    ↓ 调用 async progress_callback(message, step, total_steps)
    ↓
真实的异步进度处理
```

## 🧪 测试验证

### 1. 参数兼容性测试
```
✅ 1个参数: callback(message)
✅ 2个参数: callback(message, step)  
✅ 3个参数: callback(message, step, total_steps)
```

### 2. 真实场景测试
```
✅ run_stock_analysis调用: progress_callback("🚀 开始分析...", 1, 10)
✅ sync_progress_callback接收: (message, step=1, total_steps=10)
✅ async_progress_callback处理: 正常执行
```

## 📊 修复前后对比

### 修复前
- ❌ `sync_progress_callback(message, step=None)` - 只支持2个参数
- ❌ 调用3个参数时报错: "takes from 1 to 2 positional arguments but 3 were given"
- ❌ 后端分析服务无法正常工作

### 修复后  
- ✅ `sync_progress_callback(message, step=None, total_steps=None)` - 支持3个参数
- ✅ 兼容所有参数组合: 1个、2个、3个参数
- ✅ 后端分析服务正常工作
- ✅ 进度回调正确传递到前端

## 🎯 关键修复点

### 1. 核心问题
- **文件**: `backend/services/analysis_service.py`
- **行号**: 第205行
- **函数**: `sync_progress_callback`
- **修复**: 添加 `total_steps: int = None` 参数

### 2. 影响范围
- ✅ 后端分析服务 (`backend/services/analysis_service.py`)
- ✅ 服务器端回调 (`backend/tradingagents_server.py`) 
- ✅ 前端进度显示 (React组件)
- ✅ 实时进度更新

## 🚀 部署验证

### 1. 重启后端服务
```bash
# 如果使用Docker
docker-compose restart backend

# 如果直接运行
python backend/tradingagents_server.py
```

### 2. 验证效果
- ✅ 启动股票分析
- ✅ 观察后端日志，不再出现参数错误
- ✅ 前端正常显示进度更新
- ✅ 分析流程完整执行

## 📋 完整修复清单

- ✅ **backend/services/analysis_service.py** - sync_progress_callback支持3个参数
- ✅ **backend/services/analysis_service.py** - async_progress_callback支持3个参数  
- ✅ **backend/tradingagents_server.py** - progress_callback支持3个参数
- ✅ **web/utils/analysis_runner.py** - progress_callback支持3个参数
- ✅ **web/app.py** - progress_callback支持3个参数

## 🎉 预期结果

修复后，用户应该看到：

### 后端日志
```
✅ 不再出现: "takes from 1 to 2 positional arguments but 3 were given"
✅ 正常显示: "📊 收集市场数据..." 等进度消息
✅ 分析流程: 完整执行7步分析系统
```

### 前端界面
```
✅ 实时进度: 10% → 25% → 40% → 50% → 60% → 85% → 100%
✅ 当前状态: "正在执行 基本面分析..."
✅ 分析结果: 正常显示完整报告
```

**现在后端的progress_callback参数错误已完全修复！** 🎯✨